<?xml version="1.0"?>

<robot name="kuka_robot" xmlns:xacro="http://www.ros.org/wiki/xacro">

<xacro:include filename="$(find kuka_robot)/gazebo/kuka_robot_materials.gazebo" />
<xacro:include filename="$(find kuka_robot)/gazebo/kuka_robot_physics.gazebo" />
<xacro:include filename="$(find kuka_robot)/gazebo/kuka_robot_plugins.gazebo" />
  
  <material name="black">
    <color rgba="0.0 0.0 0.0 1.0"/>
  </material>
  <material name="orange">
    <color rgba="1.0 0.4 0.0 1.0"/>
  </material>



  <link name="world"/>
  <joint name="joint_w" type="fixed">
      <parent link="world"/>
      <child link="base_link"/>
  </joint>

  <link
    name="base_link">
    <inertial>
      <origin
        xyz="1.79063957104576E-07 1.67572848115813E-07 0.0455652610554416"
        rpy="0 0 0" />
      <mass
        value="1.28304057321319" />
      <inertia
        ixx="0.00243929811361957"
        ixy="-6.69773780277732E-09"
        ixz="1.30327760657331E-08"
        iyy="0.00243914161661202"
        iyz="-1.98358415946474E-09"
        izz="0.00271720853526469" />
    </inertial>
    <visual>
      <origin
        xyz="0 0 0"
        rpy="0 0 0" />
      <geometry>
        <mesh
          filename="package://kuka_robot/meshes/visual/base_link.STL" />
      </geometry>
      <material
        name="black">
        <color
          rgba="0.898039215686275 0.898039215686275 0.898039215686275 1" />
      </material>
    </visual>
    <collision>
      <origin
        xyz="0 0 0"
        rpy="0 0 0" />
      <geometry>
        <mesh
          filename="package://kuka_robot/meshes/collision/base_link.stl" />
      </geometry>
    </collision>
  </link>
  <link
    name="lower1_link">
    <inertial>
      <origin
        xyz="0.0174331004365116 -5.99764185868542E-05 0.087017892040276"
        rpy="0 0 0" />
      <mass
        value="1.07354479772155" />
      <inertia
        ixx="0.00244068573751809"
        ixy="9.30662734344186E-07"
        ixz="1.11099074026819E-05"
        iyy="0.00250180771402148"
        iyz="1.10140269966889E-06"
        izz="0.00107649611048839" />
    </inertial>
    <visual>
      <origin
        xyz="0 0 0"
        rpy="0 0 0" />
      <geometry>
        <mesh
          filename="package://kuka_robot/meshes/visual/lower1_link.STL" />
      </geometry>
      <material
        name="black">
        <color
          rgba="0.690196078431373 0.611764705882353 0.529411764705882 1" />
      </material>
    </visual>
    <collision>
      <origin
        xyz="0 0 0"
        rpy="0 0 0" />
      <geometry>
        <mesh
          filename="package://kuka_robot/meshes/collision/lower1_link.stl" />
      </geometry>
    </collision>
  </link>
  <joint
    name="lower1_joint"
    type="revolute">
    <origin
      xyz="0 0 0.12"
      rpy="0 0 0" />
    <parent
      link="base_link" />
    <child
      link="lower1_link" />
    <axis
      xyz="0 0 -1" />
    <limit
      lower="-6.2832"
      upper="6.2832"
      effort="30"
      velocity="17.436" />
  </joint>
  <link
    name="lower2_link">
    <inertial>
      <origin
        xyz="-0.035975 -6.2249E-05 0.069787"
        rpy="0 0 0" />
      <mass
        value="1.0343" />
      <inertia
        ixx="0.0024294"
        ixy="-9.3026E-07"
        ixz="1.1111E-05"
        iyy="0.0024915"
        iyz="-1.1007E-06"
        izz="0.0010652" />
    </inertial>
    <visual>
      <origin
        xyz="0 0 0"
        rpy="0 0 0" />
      <geometry>
        <mesh
          filename="package://kuka_robot/meshes/visual/lower2_link.STL" />
      </geometry>
      <material
        name="orange">
        <color
          rgba="0.6902 0.61176 0.52941 1" />
      </material>
    </visual>
    <collision>
      <origin
        xyz="0 0 0"
        rpy="0 0 0" />
      <geometry>
        <mesh
          filename="package://kuka_robot/meshes/collision/lower2_link.stl" />
      </geometry>
    </collision>
  </link>
  <joint
    name="lower2_joint"
    type="revolute">
    <origin
      xyz="-0.0225 0 0.1575"
      rpy="0 0 0" />
    <parent
      link="lower1_link" />
    <child
      link="lower2_link" />
    <axis
      xyz="-1 0 0" />
    <limit
      lower="-1.5708"
      upper="1.5708"
      effort="30"
      velocity="6.545" />
  </joint>
  <link
    name="upper1_link">
    <inertial>
      <origin
        xyz="-0.0174331019130241 5.99801616293706E-05 0.0870178878220682"
        rpy="0 0 0" />
      <mass
        value="1.0735453518097" />
      <inertia
        ixx="0.00244068580801946"
        ixy="9.30255309026512E-07"
        ixz="-1.11105912349513E-05"
        iyy="0.00250180701967206"
        iyz="-1.10088720657593E-06"
        izz="0.00107649557818183" />
    </inertial>
    <visual>
      <origin
        xyz="0 0 0"
        rpy="0 0 0" />
      <geometry>
        <mesh
          filename="package://kuka_robot/meshes/visual/upper1_link.STL" />
      </geometry>
      <material
        name="orange">
        <color
          rgba="0.690196078431373 0.611764705882353 0.529411764705882 1" />
      </material>
    </visual>
    <collision>
      <origin
        xyz="0 0 0"
        rpy="0 0 0" />
      <geometry>
        <mesh
          filename="package://kuka_robot/meshes/collision/upper1_link.stl" />
      </geometry>
    </collision>
  </link>
  <joint
    name="upper1_joint"
    type="revolute">
    <origin
      xyz="-0.0175 0 0.1975"
      rpy="0 0 0" />
    <parent
      link="lower2_link" />
    <child
      link="upper1_link" />
    <axis
      xyz="0 0 -1" />
    <limit
      lower="-6.2832"
      upper="6.2832"
      effort="30"
      velocity="6.545" />
  </joint>
  <link
    name="upper2_link">
    <inertial>
      <origin
        xyz="0.0359746974003218 6.22537230351066E-05 0.0697872824876592"
        rpy="0 0 0" />
      <mass
        value="1.03427543527388" />
      <inertia
        ixx="0.00242939370427471"
        ixy="-9.30256106703281E-07"
        ixz="-1.111055467359E-05"
        iyy="0.00249149448285047"
        iyz="1.10083904881362E-06"
        izz="0.00106520333340543" />
    </inertial>
    <visual>
      <origin
        xyz="0 0 0"
        rpy="0 0 0" />
      <geometry>
        <mesh
          filename="package://kuka_robot/meshes/visual/upper2_link.STL" />
      </geometry>
      <material
        name="black">
        <color
          rgba="0.690196078431373 0.611764705882353 0.529411764705882 1" />
      </material>
    </visual>
    <collision>
      <origin
        xyz="0 0 0"
        rpy="0 0 0" />
      <geometry>
        <mesh
          filename="package://kuka_robot/meshes/collision/upper2_link.stl" />
      </geometry>
    </collision>
  </link>
  <joint
    name="upper2_joint"
    type="revolute">
    <origin
      xyz="0.0225 0 0.1575"
      rpy="0 0 0" />
    <parent
      link="upper1_link" />
    <child
      link="upper2_link" />
    <axis
      xyz="1 0 0" />
    <limit
      lower="-2.3562"
      upper="2.3562"
      effort="30"
      velocity="6.545" />
  </joint>
  <link
    name="top_link">
    <inertial>
      <origin
        xyz="0.0127923259892452 -1.22225312032995E-06 0.0357599837468831"
        rpy="0 0 0" />
      <mass
        value="0.253283687997405" />
      <inertia
        ixx="0.000292417828240087"
        ixy="-1.43077437091592E-08"
        ixz="-8.63612197923442E-05"
        iyy="0.00041545832790866"
        iyz="-5.0332513868308E-09"
        izz="0.000389340874992559" />
    </inertial>
    <visual>
      <origin
        xyz="0 0 0"
        rpy="0 0 0" />
      <geometry>
        <mesh
          filename="package://kuka_robot/meshes/visual/top_link.STL" />
      </geometry>
      <material
        name="orange">
        <color
          rgba="0.690196078431373 0.611764705882353 0.529411764705882 1" />
      </material>
    </visual>
    <collision>
      <origin
        xyz="0 0 0"
        rpy="0 0 0" />
      <geometry>
        <mesh
          filename="package://kuka_robot/meshes/collision/top_link.stl" />
      </geometry>
    </collision>
  </link>
  <joint
    name="top_joint"
    type="revolute">
    <origin
      xyz="0.0175 0 0.1875"
      rpy="0 0 0" />
    <parent
      link="upper2_link" />
    <child
      link="top_link" />
    <axis
      xyz="0 0 -1" />
    <limit
      lower="-6.2832"
      upper="6.2832"
      effort="30"
      velocity="6.545" />
  </joint>
  <link
    name="end_effector_link">
    <inertial>
      <origin
        xyz="-0.042834 2.151E-07 0.027882"
        rpy="0 0 0" />
      <mass
        value="0.24233" />
      <inertia
        ixx="0.00021015"
        ixy="1.2933E-09"
        ixz="1.3983E-05"
        iyy="0.00024828"
        iyz="1.0496E-09"
        izz="0.00011469" />
    </inertial>
    <visual>
      <origin
        xyz="0 0 0"
        rpy="0 0 0" />
      <geometry>
        <mesh
          filename="package://kuka_robot/meshes/visual/end_effector_link.STL" />
      </geometry>
      <material
        name="black">
        <color
          rgba="0.6902 0.61176 0.52941 1" />
      </material>
    </visual>
    <collision>
      <origin
        xyz="0 0 0"
        rpy="0 0 0" />
      <geometry>
        <mesh
          filename="package://kuka_robot/meshes/collision/end_effector_link.stl" />
      </geometry>
    </collision>
  </link>
  <joint
    name="end_effector_joint"
    type="revolute">
    <origin
      xyz="0.0312 0 0.15"
      rpy="0 0 0" />
    <parent
      link="top_link" />
    <child
      link="end_effector_link" />
    <axis
      xyz="1 0 0" />
    <limit
      lower="-2.3562"
      upper="2.3562"
      effort="30"
      velocity="6.545" />
  </joint>
  
</robot>
